<?xml version="1.0"?>
<!-- This URDF was automatically created by SolidWorks to URDF Exporter! Originally created by Stephen Brawner (brawner@gmail.com) 
     Commit Version: 1.6.0-4-g7f85cfe  Build Version: 1.6.7995.38578
     For more information, please see http://wiki.ros.org/sw_urdf_exporter -->
<robot
  name="sentry">
  <link
    name="base_link">

    <!-- 需要注意的是，对于base_link而言，不可以在其中添加<inertial></inertial>标签，否则会出现报错 -->

    <!-- <inertial>
      <origin
        xyz="-0.0361652072991743 0.0209571563714629 0.0360265460101268"
        rpy="0 0 0" />
      <mass
        value="23.1391773877476" />
      <inertia
        ixx="0.0901948959488623"
        ixy="-0.000344245037062967"
        ixz="0.000224432800112885"
        iyy="0.11386885550254"
        iyz="6.89890451243286E-05"
        izz="0.182487467777796" />
    </inertial> -->
    <visual>
      <origin
        xyz="0 0 0"
        rpy="0 0 0" />
      <geometry>

        <!-- 此处的路径是相对路径，一定小心不要在package://前输入空格，否则会出现Error retrieving的错误
        而对于由脚本直接生成的ros2 python包而言需要在下列路径修改为<mesh filename="package://sentry/meshes/visual/base_link.STL" />

        如果相对路径不可用,需要修改为绝对路径时，绝对路径应为install文件夹下STL文件的位置 -->

        <mesh
          filename="package://sentry/meshes/base_link.STL" />
      </geometry>
      <material
        name="">
        <color
          rgba="1 1 1 1" />
      </material>
    </visual>
    <collision>
      <origin
        xyz="0 0 0"
        rpy="0 0 0" />
      <geometry>
        <mesh
          filename="package://sentry/meshes/base_link.STL" />
      </geometry>
    </collision>
  </link>
  <link
    name="chassis">
    <inertial>
      <origin
        xyz="-0.0349327596773196 0.0382115103474763 -0.0455017969182153"
        rpy="0 0 0" />
      <mass
        value="2.6927008419585" />
      <inertia
        ixx="0.00214512641346786"
        ixy="-1.76962204845044E-17"
        ixz="-8.00646477643671E-05"
        iyy="0.0117293736430865"
        iyz="-1.81806157902634E-17"
        izz="0.0118045045747028" />
    </inertial>
    <visual>
      <origin
        xyz="0 0 0"
        rpy="0 0 0" />
      <geometry>
        <mesh
          filename="package://sentry/meshes/chassis.STL" />
      </geometry>
      <material
        name="">
        <color
          rgba="0.792156862745098 0.819607843137255 0.933333333333333 1" />
      </material>
    </visual>
    <collision>
      <origin
        xyz="0 0 0"
        rpy="0 0 0" />
      <geometry>
        <mesh
          filename="package://sentry/meshes/chassis.STL" />
      </geometry>
    </collision>
  </link>
  <joint
    name="chassis_joint"
    type="fixed">
    <origin
      xyz="0 0 0"
      rpy="0 0 0" />
    <parent
      link="base_link" />
    <child
      link="chassis" />
    <axis
      xyz="0 0 0" />
  </joint>
  <link
    name="left_front_wheel">
    <inertial>
      <origin
        xyz="7.59771157593514E-06 -0.00307892908921081 2.86036781343979E-07"
        rpy="0 0 0" />
      <mass
        value="1.82875771556047" />
      <inertia
        ixx="0.000829516125149062"
        ixy="2.11795043888543E-07"
        ixz="-1.74967399702358E-06"
        iyy="0.00147372135092557"
        iyz="-7.83370323131437E-07"
        izz="0.000830406126477844" />
    </inertial>
    <visual>
      <origin
        xyz="0 0 0"
        rpy="0 0 0" />
      <geometry>
        <mesh
          filename="package://sentry/meshes/left_front_wheel.STL" />
      </geometry>
      <material
        name="">
        <color
          rgba="0.647058823529412 0.619607843137255 0.588235294117647 1" />
      </material>
    </visual>
    <collision>
      <origin
        xyz="0 0 0"
        rpy="0 0 0" />
      <geometry>
        <mesh
          filename="package://sentry/meshes/left_front_wheel.STL" />
      </geometry>
    </collision>
  </link>
  <joint
    name="left_front_wheel_joint"
    type="continuous">
    <origin
      xyz="0.235483156242427 0.209187900001645 -0.0787868895364084"
      rpy="0 0 0" />
    <parent
      link="chassis" />
    <child
      link="left_front_wheel" />
    <axis
      xyz="0 -1 0" />
  </joint>
  <link
    name="left_back_wheel">
    <inertial>
      <origin
        xyz="-7.60491498300042E-06 -0.0126039289248186 2.87325576095454E-07"
        rpy="0 0 0" />
      <mass
        value="1.82875572247492" />
      <inertia
        ixx="0.000829514377504731"
        ixy="-2.11810286474946E-07"
        ixz="1.74568714659959E-06"
        iyy="0.00147370408626826"
        iyz="-7.83465790589973E-07"
        izz="0.00083039068183486" />
    </inertial>
    <visual>
      <origin
        xyz="0 0 0"
        rpy="0 0 0" />
      <geometry>
        <mesh
          filename="package://sentry/meshes/left_back_wheel.STL" />
      </geometry>
      <material
        name="">
        <color
          rgba="0.647058823529412 0.619607843137255 0.588235294117647 1" />
      </material>
    </visual>
    <collision>
      <origin
        xyz="0 0 0"
        rpy="0 0 0" />
      <geometry>
        <mesh
          filename="package://sentry/meshes/left_back_wheel.STL" />
      </geometry>
    </collision>
  </link>
  <joint
    name="left_back_wheel_joint"
    type="continuous">
    <origin
      xyz="-0.235483156242427 0.218712899998355 -0.0787868895364084"
      rpy="0 0 0" />
    <parent
      link="chassis" />
    <child
      link="left_back_wheel" />
    <axis
      xyz="0 -1 0" />
  </joint>
  <link
    name="right_front_wheel">
    <inertial>
      <origin
        xyz="2.09252245874647E-05 0.00159845488727364 -4.05090856175905E-06"
        rpy="0 0 0" />
      <mass
        value="0.333100209927993" />
      <inertia
        ixx="0.000117101887569571"
        ixy="-2.69823967871697E-08"
        ixz="-8.75430047850941E-07"
        iyy="0.000204978710848938"
        iyz="9.98052935971376E-08"
        izz="0.000114994491962305" />
    </inertial>
    <visual>
      <origin
        xyz="0 0 0"
        rpy="0 0 0" />
      <geometry>
        <mesh
          filename="package://sentry/meshes/right_front_wheel.STL" />
      </geometry>
      <material
        name="">
        <color
          rgba="1 1 1 1" />
      </material>
    </visual>
    <collision>
      <origin
        xyz="0 0 0"
        rpy="0 0 0" />
      <geometry>
        <mesh
          filename="package://sentry/meshes/right_front_wheel.STL" />
      </geometry>
    </collision>
  </link>
  <joint
    name="right_front_wheel_joint"
    type="continuous">
    <origin
      xyz="0.235483156242427 -0.208734549339245 -0.0787868895364084"
      rpy="0 0 0" />
    <parent
      link="chassis" />
    <child
      link="right_front_wheel" />
    <axis
      xyz="0 -1 0" />
  </joint>
  <link
    name="right_back_wheel">
    <inertial>
      <origin
        xyz="-7.5978383736186E-06 0.0141914291260262 2.85788811629772E-07"
        rpy="0 0 0" />
      <mass
        value="1.82875772371481" />
      <inertia
        ixx="0.000829516128053615"
        ixy="2.11796083257462E-07"
        ixz="1.74968513077768E-06"
        iyy="0.00147372137065289"
        iyz="7.83370833627999E-07"
        izz="0.000830406144468111" />
    </inertial>
    <visual>
      <origin
        xyz="0 0 0"
        rpy="0 0 0" />
      <geometry>
        <mesh
          filename="package://sentry/meshes/right_back_wheel.STL" />
      </geometry>
      <material
        name="">
        <color
          rgba="0.647058823529412 0.619607843137255 0.588235294117647 1" />
      </material>
    </visual>
    <collision>
      <origin
        xyz="0 0 0"
        rpy="0 0 0" />
      <geometry>
        <mesh
          filename="package://sentry/meshes/right_back_wheel.STL" />
      </geometry>
    </collision>
  </link>
  <joint
    name="right_back_wheel_joint"
    type="continuous">
    <origin
      xyz="-0.235483156242427 -0.2203004 -0.0787868895364083"
      rpy="0 0 0" />
    <parent
      link="chassis" />
    <child
      link="right_back_wheel" />
    <axis
      xyz="0 -1 0" />
  </joint>
  <link
    name="armor_front">
    <inertial>
      <origin
        xyz="0.304169771213995 5.43211370419881E-08 -0.0237422383507312"
        rpy="0 0 0" />
      <mass
        value="0.152235534501031" />
      <inertia
        ixx="0.000323738587658112"
        ixy="-7.65249917673618E-12"
        ixz="4.50635223771784E-05"
        iyy="0.000205729056850688"
        iyz="1.32713414121881E-10"
        izz="0.000174734064837662" />
    </inertial>
    <visual>
      <origin
        xyz="0 0 0"
        rpy="0 0 0" />
      <geometry>
        <mesh
          filename="package://sentry/meshes/armor_front.STL" />
      </geometry>
      <material
        name="">
        <color
          rgba="0.792156862745098 0.819607843137255 0.933333333333333 1" />
      </material>
    </visual>
    <collision>
      <origin
        xyz="0 0 0"
        rpy="0 0 0" />
      <geometry>
        <mesh
          filename="package://sentry/meshes/armor_front.STL" />
      </geometry>
    </collision>
  </link>
  <joint
    name="armor_front_joint"
    type="fixed">
    <origin
      xyz="0 0 0"
      rpy="0 0 0" />
    <parent
      link="chassis" />
    <child
      link="armor_front" />
    <axis
      xyz="0 0 0" />
  </joint>
  <link
    name="armor_front_indicator">
    <inertial>
      <origin
        xyz="0.31863584566516 9.99999999998444E-05 -0.0258716707172072"
        rpy="0 0 0" />
      <mass
        value="0.00325604020999811" />
      <inertia
        ixx="7.37692753148457E-07"
        ixy="-3.72607280752131E-14"
        ixz="1.927514493232E-07"
        iyy="7.81039828156082E-07"
        iyz="1.3905892959049E-13"
        izz="6.99821462277301E-08" />
    </inertial>
    <visual>
      <origin
        xyz="0 0 0"
        rpy="0 0 0" />
      <geometry>
        <mesh
          filename="package://sentry/meshes/armor_front_indicator.STL" />
      </geometry>
      <material
        name="">
        <color
          rgba="1 0 0 1" />
      </material>
    </visual>
    <collision>
      <origin
        xyz="0 0 0"
        rpy="0 0 0" />
      <geometry>
        <mesh
          filename="package://sentry/meshes/armor_front_indicator.STL" />
      </geometry>
    </collision>
  </link>
  <joint
    name="armor_front_indicator_joint"
    type="fixed">
    <origin
      xyz="0 0 0"
      rpy="0 0 0" />
    <parent
      link="armor_front" />
    <child
      link="armor_front_indicator" />
    <axis
      xyz="0 0 0" />
  </joint>
  <link
    name="armor_back">
    <inertial>
      <origin
        xyz="-0.303506227715662 5.43954077960527E-08 -0.0212658633884312"
        rpy="0 0 0" />
      <mass
        value="0.15223552650775" />
      <inertia
        ixx="0.000325513595591753"
        ixy="-5.96652531959849E-11"
        ixz="-4.19890869825068E-05"
        iyy="0.000205729050154244"
        iyz="-1.16105342907172E-10"
        izz="0.000172959035247242" />
    </inertial>
    <visual>
      <origin
        xyz="0 0 0"
        rpy="0 0 0" />
      <geometry>
        <mesh
          filename="package://sentry/meshes/armor_back.STL" />
      </geometry>
      <material
        name="">
        <color
          rgba="0.792156862745098 0.819607843137255 0.933333333333333 1" />
      </material>
    </visual>
    <collision>
      <origin
        xyz="0 0 0"
        rpy="0 0 0" />
      <geometry>
        <mesh
          filename="package://sentry/meshes/armor_back.STL" />
      </geometry>
    </collision>
  </link>
  <joint
    name="armor_back_joint"
    type="fixed">
    <origin
      xyz="0 0 0"
      rpy="0 0 0" />
    <parent
      link="chassis" />
    <child
      link="armor_back" />
    <axis
      xyz="0 0 0" />
  </joint>
  <link
    name="armor_back_indicator">
    <inertial>
      <origin
        xyz="-0.314969500398791 9.99999999999199E-05 -0.0121886839050259"
        rpy="0 0 0" />
      <mass
        value="0.00325604020999812" />
      <inertia
        ixx="7.37692753148454E-07"
        ixy="-3.72607280791385E-14"
        ixz="-1.92751449323207E-07"
        iyy="7.81039828156082E-07"
        iyz="-1.39058931067943E-13"
        izz="6.99821462277338E-08" />
    </inertial>
    <visual>
      <origin
        xyz="0 0 0"
        rpy="0 0 0" />
      <geometry>
        <mesh
          filename="package://sentry/meshes/armor_back_indicator.STL" />
      </geometry>
      <material
        name="">
        <color
          rgba="1 0 0 1" />
      </material>
    </visual>
    <collision>
      <origin
        xyz="0 0 0"
        rpy="0 0 0" />
      <geometry>
        <mesh
          filename="package://sentry/meshes/armor_back_indicator.STL" />
      </geometry>
    </collision>
  </link>
  <joint
    name="armor_back_indicator_joint"
    type="fixed">
    <origin
      xyz="0 0 0"
      rpy="0 0 0" />
    <parent
      link="armor_back" />
    <child
      link="armor_back_indicator" />
    <axis
      xyz="0 0 0" />
  </joint>
  <link
    name="armor_left">
    <inertial>
      <origin
        xyz="-5.42976966181171E-08 0.242169771213585 0.0292577616401522"
        rpy="0 0 0" />
      <mass
        value="0.152235534429326" />
      <inertia
        ixx="0.000205729056816187"
        ixy="7.66021400672615E-12"
        ixz="-1.32799926114352E-10"
        iyy="0.000323738587433552"
        iyz="4.50635223723233E-05"
        izz="0.00017473406464879" />
    </inertial>
    <visual>
      <origin
        xyz="0 0 0"
        rpy="0 0 0" />
      <geometry>
        <mesh
          filename="package://sentry/meshes/armor_left.STL" />
      </geometry>
      <material
        name="">
        <color
          rgba="0.792156862745098 0.819607843137255 0.933333333333333 1" />
      </material>
    </visual>
    <collision>
      <origin
        xyz="0 0 0"
        rpy="0 0 0" />
      <geometry>
        <mesh
          filename="package://sentry/meshes/armor_left.STL" />
      </geometry>
    </collision>
  </link>
  <joint
    name="armor_left_joint"
    type="fixed">
    <origin
      xyz="0 0 0"
      rpy="0 0 0" />
    <parent
      link="chassis" />
    <child
      link="armor_left" />
    <axis
      xyz="0 0 0" />
  </joint>
  <link
    name="armor_left_indicator">
    <inertial>
      <origin
        xyz="-0.000100000000001661 0.256635845665169 0.0271283292827911"
        rpy="0 0 0" />
      <mass
        value="0.00325604020999811" />
      <inertia
        ixx="7.81039828156081E-07"
        ixy="3.72607286595072E-14"
        ixz="-1.39058931474129E-13"
        iyy="7.37692753148455E-07"
        iyz="1.927514493232E-07"
        izz="6.99821462277306E-08" />
    </inertial>
    <visual>
      <origin
        xyz="0 0 0"
        rpy="0 0 0" />
      <geometry>
        <mesh
          filename="package://sentry/meshes/armor_left_indicator.STL" />
      </geometry>
      <material
        name="">
        <color
          rgba="1 0 0 1" />
      </material>
    </visual>
    <collision>
      <origin
        xyz="0 0 0"
        rpy="0 0 0" />
      <geometry>
        <mesh
          filename="package://sentry/meshes/armor_left_indicator.STL" />
      </geometry>
    </collision>
  </link>
  <joint
    name="armor_left_indicator_joint"
    type="fixed">
    <origin
      xyz="0 0 0"
      rpy="0 0 0" />
    <parent
      link="armor_left" />
    <child
      link="armor_left_indicator" />
    <axis
      xyz="0 0 0" />
  </joint>
  <link
    name="armor_right">
    <inertial>
      <origin
        xyz="5.43211366727758E-08 -0.242169771214003 0.0292577616492671"
        rpy="0 0 0" />
      <mass
        value="0.152235534501031" />
      <inertia
        ixx="0.000205729056850687"
        ixy="7.65249961094956E-12"
        ixz="1.3271341448978E-10"
        iyy="0.000323738587658111"
        iyz="-4.50635223771781E-05"
        izz="0.000174734064837663" />
    </inertial>
    <visual>
      <origin
        xyz="0 0 0"
        rpy="0 0 0" />
      <geometry>
        <mesh
          filename="package://sentry/meshes/armor_right.STL" />
      </geometry>
      <material
        name="">
        <color
          rgba="0.792156862745098 0.819607843137255 0.933333333333333 1" />
      </material>
    </visual>
    <collision>
      <origin
        xyz="0 0 0"
        rpy="0 0 0" />
      <geometry>
        <mesh
          filename="package://sentry/meshes/armor_right.STL" />
      </geometry>
    </collision>
  </link>
  <joint
    name="armor_right_joint"
    type="fixed">
    <origin
      xyz="0 0 0"
      rpy="0 0 0" />
    <parent
      link="chassis" />
    <child
      link="armor_right" />
    <axis
      xyz="0 0 0" />
  </joint>
  <link
    name="armor_right_indicator">
    <inertial>
      <origin
        xyz="9.99999999993009E-05 -0.256635845665169 0.0271283292827911"
        rpy="0 0 0" />
      <mass
        value="0.0032560402099981" />
      <inertia
        ixx="7.81039828156079E-07"
        ixy="3.72607280657377E-14"
        ixz="1.39058929485271E-13"
        iyy="7.37692753148455E-07"
        iyz="-1.927514493232E-07"
        izz="6.99821462277299E-08" />
    </inertial>
    <visual>
      <origin
        xyz="0 0 0"
        rpy="0 0 0" />
      <geometry>
        <mesh
          filename="package://sentry/meshes/armor_right_indicator.STL" />
      </geometry>
      <material
        name="">
        <color
          rgba="1 0 0 1" />
      </material>
    </visual>
    <collision>
      <origin
        xyz="0 0 0"
        rpy="0 0 0" />
      <geometry>
        <mesh
          filename="package://sentry/meshes/armor_right_indicator.STL" />
      </geometry>
    </collision>
  </link>
  <joint
    name="armor_right_indicator_joint"
    type="fixed">
    <origin
      xyz="0 0 0"
      rpy="0 0 0" />
    <parent
      link="armor_right" />
    <child
      link="armor_right_indicator" />
    <axis
      xyz="0 0 0" />
  </joint>
  <link
    name="upgimbal_link">
    <inertial>
      <origin
        xyz="0.0339462701413684 0.020711650828539 0.0990139499368337"
        rpy="0 0 0" />
      <mass
        value="1.51180178392616" />
      <inertia
        ixx="0.00153572265225156"
        ixy="-1.84730225262693E-05"
        ixz="0.00022103736823766"
        iyy="0.00213859582676009"
        iyz="8.92024707234992E-06"
        izz="0.0028211375437379" />
    </inertial>
    <visual>
      <origin
        xyz="0 0 0"
        rpy="0 0 0" />
      <geometry>
        <mesh
          filename="package://sentry/meshes/upgimbal_link.STL" />
      </geometry>
      <material
        name="">
        <color
          rgba="1 1 1 1" />
      </material>
    </visual>
    <collision>
      <origin
        xyz="0 0 0"
        rpy="0 0 0" />
      <geometry>
        <mesh
          filename="package://sentry/meshes/upgimbal_link.STL" />
      </geometry>
    </collision>
  </link>
  <joint
    name="upgimbal_link_joint"
    type="continuous">
    <origin
      xyz="0 0 0.309999999999993"
      rpy="0 0 0" />
    <parent
      link="base_link" />
    <child
      link="upgimbal_link" />
    <axis
      xyz="0 0 1" />
  </joint>
  <link
    name="upcamera_link">
    <inertial>
      <origin
        xyz="-0.0414593437557629 -5.18953505232525E-05 -0.00224647113736637"
        rpy="0 0 0" />
      <mass
        value="0.0904026699159145" />
      <inertia
        ixx="2.69489107662312E-05"
        ixy="-4.91346507949079E-08"
        ixz="-4.26444849113399E-07"
        iyy="3.5670228780648E-05"
        iyz="4.30129247074387E-08"
        izz="3.77189356895724E-05" />
    </inertial>
    <visual>
      <origin
        xyz="0 0 0"
        rpy="0 0 0" />
      <geometry>
        <mesh
          filename="package://sentry/meshes/upcamera_link.STL" />
      </geometry>
      <material
        name="">
        <color
          rgba="0.792156862745098 0.819607843137255 0.933333333333333 1" />
      </material>
    </visual>
    <collision>
      <origin
        xyz="0 0 0"
        rpy="0 0 0" />
      <geometry>
        <mesh
          filename="package://sentry/meshes/upcamera_link.STL" />
      </geometry>
    </collision>
  </link>
  <joint
    name="upcamera_link_joint"
    type="fixed">
    <origin
      xyz="0.174051874455189 -0.00197340047587015 0.111954878139203"
      rpy="0.0137672832640321 0.442742365424449 0.00589847026704101" />
    <parent
      link="upgimbal_link" />
    <child
      link="upcamera_link" />
    <axis
      xyz="0 0 0" />
  </joint>
  <link
    name="upbarrel_link">
    <inertial>
      <origin
        xyz="-0.0490253901089761 7.21849882766466E-05 -0.000561846239159391"
        rpy="0 0 0" />
      <mass
        value="0.215832434707193" />
      <inertia
        ixx="4.25561020681325E-05"
        ixy="1.16534021582705E-06"
        ixz="5.70980975097776E-06"
        iyy="0.000180116754252072"
        iyz="5.32210214887407E-08"
        izz="0.000191289878367335" />
    </inertial>
    <visual>
      <origin
        xyz="0 0 0"
        rpy="0 0 0" />
      <geometry>
        <mesh
          filename="package://sentry/meshes/upbarrel_link.STL" />
      </geometry>
      <material
        name="">
        <color
          rgba="0.752941176470588 0.752941176470588 0.752941176470588 1" />
      </material>
    </visual>
    <collision>
      <origin
        xyz="0 0 0"
        rpy="0 0 0" />
      <geometry>
        <mesh
          filename="package://sentry/meshes/upbarrel_link.STL" />
      </geometry>
    </collision>
  </link>
  <joint
    name="upbarrel_link_joint"
    type="fixed">
    <origin
      xyz="0.130928658474544 -0.00222764986082413 0.0797892999814742"
      rpy="0.013767283264024 0.442742365424448 0.00589847026703752" />
    <parent
      link="upgimbal_link" />
    <child
      link="upbarrel_link" />
    <axis
      xyz="0 0 0" />
  </joint>
  <link
    name="upIMU_link">
    <inertial>
      <origin
        xyz="-0.00107062049079942 -0.000126792725251131 -0.00487412751698818"
        rpy="0 0 0" />
      <mass
        value="0.0159371927735237" />
      <inertia
        ixx="3.50288332094385E-06"
        ixy="-2.92906733367087E-08"
        ixz="3.35761041099977E-09"
        iyy="1.99089788508288E-06"
        iyz="5.18445947128511E-08"
        izz="5.46940895941554E-06" />
    </inertial>
    <visual>
      <origin
        xyz="0 0 0"
        rpy="0 0 0" />
      <geometry>
        <mesh
          filename="package://sentry/meshes/upIMU_link.STL" />
      </geometry>
      <material
        name="">
        <color
          rgba="0.796078431372549 0.823529411764706 0.937254901960784 1" />
      </material>
    </visual>
    <collision>
      <origin
        xyz="0 0 0"
        rpy="0 0 0" />
      <geometry>
        <mesh
          filename="package://sentry/meshes/upIMU_link.STL" />
      </geometry>
    </collision>
  </link>
  <joint
    name="upIMU_link_joint"
    type="fixed">
    <origin
      xyz="0.0141603828305071 -0.00271561732633889 0.184445666984459"
      rpy="0.0137672832640244 0.442742365424449 0.00589847026703774" />
    <parent
      link="upgimbal_link" />
    <child
      link="upIMU_link" />
    <axis
      xyz="0 0 0" />
  </joint>
  <link
    name="up_cmd_yaw">
    <inertial>
      <origin
        xyz="-0.00341811191754958 -0.00125492064510141 0.016577773557204"
        rpy="0 0 0" />
      <mass
        value="0.270321194897485" />
      <inertia
        ixx="9.38085393208138E-05"
        ixy="3.7030816714672E-07"
        ixz="4.62077427030115E-07"
        iyy="9.28890919877556E-05"
        iyz="1.48192982130117E-07"
        izz="0.000150964050880624" />
    </inertial>
    <visual>
      <origin
        xyz="0 0 0"
        rpy="0 0 0" />
      <geometry>
        <mesh
          filename="package://sentry/meshes/up_cmd_yaw.STL" />
      </geometry>
      <material
        name="">
        <color
          rgba="0.196078431372549 0.196078431372549 0.196078431372549 1" />
      </material>
    </visual>
    <collision>
      <origin
        xyz="0 0 0"
        rpy="0 0 0" />
      <geometry>
        <mesh
          filename="package://sentry/meshes/up_cmd_yaw.STL" />
      </geometry>
    </collision>
  </link>
  <joint
    name="up_cmd_yaw_joint"
    type="continuous">
    <origin
      xyz="0.0816573110784931 0.00136726885735552 -0.197002655270223"
      rpy="-0.0124397721709154 -0.442779053817077 0" />
    <parent
      link="upIMU_link" />
    <child
      link="up_cmd_yaw" />
    <axis
      xyz="0 0 1" />
  </joint>
  <link
    name="up_cmd_pitch">
    <inertial>
      <origin
        xyz="-1.32222178163555E-05 -0.00128392205482297 -0.000126654738430931"
        rpy="0 0 0" />
      <mass
        value="0.270321194039701" />
      <inertia
        ixx="9.27646956242046E-05"
        ixy="-2.12556062639963E-08"
        ixz="8.53112351836419E-08"
        iyy="0.000150964050687294"
        iyz="-4.84793744306387E-07"
        izz="9.39329354476903E-05" />
    </inertial>
    <visual>
      <origin
        xyz="0 0 0"
        rpy="0 0 0" />
      <geometry>
        <mesh
          filename="package://sentry/meshes/up_cmd_pitch.STL" />
      </geometry>
      <material
        name="">
        <color
          rgba="0.196078431372549 0.196078431372549 0.196078431372549 1" />
      </material>
    </visual>
    <collision>
      <origin
        xyz="0 0 0"
        rpy="0 0 0" />
      <geometry>
        <mesh
          filename="package://sentry/meshes/up_cmd_pitch.STL" />
      </geometry>
    </collision>
  </link>
  <joint
    name="up_cmd_pitch_joint"
    type="continuous">
    <origin
      xyz="-0.117317026246573 0.0425293327166282 -0.0453111609744777"
      rpy="-0.0137672832640243 0 0" />
    <parent
      link="upIMU_link" />
    <child
      link="up_cmd_pitch" />
    <axis
      xyz="-0.00532970992563554 -0.999982604074691 -0.00252700219791819" />
  </joint>
  <link
    name="lidar_link">
    <inertial>
      <origin
        xyz="-0.0150898287858668 -0.00114391791308788 0.00814395246889593"
        rpy="0 0 0" />
      <mass
        value="0.251389149161401" />
      <inertia
        ixx="0.000173574970737519"
        ixy="2.77889801356545E-07"
        ixz="1.46222397831688E-09"
        iyy="0.000127402029147206"
        iyz="-4.30707034788354E-10"
        izz="0.000272998967561114" />
    </inertial>
    <visual>
      <origin
        xyz="0 0 0"
        rpy="0 0 0" />
      <geometry>
        <mesh
          filename="package://sentry/meshes/lidar_link.STL" />
      </geometry>
      <material
        name="">
        <color
          rgba="0.752941176470588 0.752941176470588 0.752941176470588 1" />
      </material>
    </visual>
    <collision>
      <origin
        xyz="0 0 0"
        rpy="0 0 0" />
      <geometry>
        <mesh
          filename="package://sentry/meshes/lidar_link.STL" />
      </geometry>
    </collision>
  </link>
  <joint
    name="lidar_link_joint"
    type="fixed">
    <origin
      xyz="0.221932828762558 0.0968107407133292 0.066349999999997"
      rpy="0 0 0" />
    <parent
      link="upgimbal_link" />
    <child
      link="lidar_link" />
    <axis
      xyz="0 0 0" />
  </joint>
  <link
    name="downgimbal_link">
    <inertial>
      <origin
        xyz="0.00131067554610981 0.00662167005990475 0.105523040175853"
        rpy="0 0 0" />
      <mass
        value="2.82614276571715" />
      <inertia
        ixx="0.00408865766889829"
        ixy="-0.000373673525200184"
        ixz="0.000387485923645416"
        iyy="0.00564594355413254"
        iyz="-4.1161480541148E-06"
        izz="0.00707217320510278" />
    </inertial>
    <visual>
      <origin
        xyz="0 0 0"
        rpy="0 0 0" />
      <geometry>
        <mesh
          filename="package://sentry/meshes/downgimbal_link.STL" />
      </geometry>
      <material
        name="">
        <color
          rgba="0.752941176470588 0.752941176470588 0.752941176470588 1" />
      </material>
    </visual>
    <collision>
      <origin
        xyz="0 0 0"
        rpy="0 0 0" />
      <geometry>
        <mesh
          filename="package://sentry/meshes/downgimbal_link.STL" />
      </geometry>
    </collision>
  </link>
  <joint
    name="downgimbal_link_joint"
    type="continuous">
    <origin
      xyz="0 0 0"
      rpy="0 0 0" />
    <parent
      link="base_link" />
    <child
      link="downgimbal_link" />
    <axis
      xyz="0 0 1" />
  </joint>
  <link
    name="downcamera_link">
    <inertial>
      <origin
        xyz="-0.0426264920382084 -0.000592783092209986 0.00176975597363566"
        rpy="0 0 0" />
      <mass
        value="0.0726607478994773" />
      <inertia
        ixx="1.51466689636253E-05"
        ixy="6.14581951766313E-07"
        ixz="-5.11758842888327E-07"
        iyy="2.7317243773639E-05"
        iyz="-2.11739247223333E-07"
        izz="2.96992649429621E-05" />
    </inertial>
    <visual>
      <origin
        xyz="0 0 0"
        rpy="0 0 0" />
      <geometry>
        <mesh
          filename="package://sentry/meshes/downcamera_link.STL" />
      </geometry>
      <material
        name="">
        <color
          rgba="0.792156862745098 0.819607843137255 0.933333333333333 1" />
      </material>
    </visual>
    <collision>
      <origin
        xyz="0 0 0"
        rpy="0 0 0" />
      <geometry>
        <mesh
          filename="package://sentry/meshes/downcamera_link.STL" />
      </geometry>
    </collision>
  </link>
  <joint
    name="downcamera_link_joint"
    type="fixed">
    <origin
      xyz="0.177692119911736 -0.0049065864019572 0.154495528960523"
      rpy="-0.0939396250069833 0.297443991350864 -0.0276058383089769" />
    <parent
      link="downgimbal_link" />
    <child
      link="downcamera_link" />
    <axis
      xyz="0 0 0" />
  </joint>
  <link
    name="downbarrel_link">
    <inertial>
      <origin
        xyz="-0.0528655022698618 -0.000257563636014008 -0.000591930849532518"
        rpy="0 0 0" />
      <mass
        value="0.225199575482026" />
      <inertia
        ixx="4.49384915071999E-05"
        ixy="-4.46586704078044E-06"
        ixz="7.25204877577098E-06"
        iyy="0.000206842637673706"
        iyz="-6.2958680345523E-07"
        izz="0.000218659361093051" />
    </inertial>
    <visual>
      <origin
        xyz="0 0 0"
        rpy="0 0 0" />
      <geometry>
        <mesh
          filename="package://sentry/meshes/downbarrel_link.STL" />
      </geometry>
      <material
        name="">
        <color
          rgba="0.752941176470588 0.752941176470588 0.752941176470588 1" />
      </material>
    </visual>
    <collision>
      <origin
        xyz="0 0 0"
        rpy="0 0 0" />
      <geometry>
        <mesh
          filename="package://sentry/meshes/downbarrel_link.STL" />
      </geometry>
    </collision>
  </link>
  <joint
    name="downbarrel_link_joint"
    type="fixed">
    <origin
      xyz="0.136457847972371 -0.00376787589476315 0.118986412475197"
      rpy="-0.0939396250069833 0.297443991350864 -0.0276058383089769" />
    <parent
      link="downgimbal_link" />
    <child
      link="downbarrel_link" />
    <axis
      xyz="0 0 0" />
  </joint>
  <link
    name="downIMU_link">
    <inertial>
      <origin
        xyz="0.00099954401933227 0.000515767182491252 -0.00509868965393581"
        rpy="0 0 0" />
      <mass
        value="0.0159371927735237" />
      <inertia
        ixx="3.50288332094387E-06"
        ixy="2.89276901066352E-08"
        ixz="5.69261252108429E-09"
        iyy="2.02148594437705E-06"
        iyz="-3.28866440408042E-07"
        izz="5.43882090012136E-06" />
    </inertial>
    <visual>
      <origin
        xyz="0 0 0"
        rpy="0 0 0" />
      <geometry>
        <mesh
          filename="package://sentry/meshes/downIMU_link.STL" />
      </geometry>
      <material
        name="">
        <color
          rgba="0.796078431372549 0.823529411764706 0.937254901960784 1" />
      </material>
    </visual>
    <collision>
      <origin
        xyz="0 0 0"
        rpy="0 0 0" />
      <geometry>
        <mesh
          filename="package://sentry/meshes/downIMU_link.STL" />
      </geometry>
    </collision>
  </link>
  <joint
    name="downIMU_link_joint"
    type="fixed">
    <origin
      xyz="0.0120939231688496 0.000590727859089427 0.204761855171752"
      rpy="-0.0939396250069833 0.297443991350864 -0.0276058383089769" />
    <parent
      link="downgimbal_link" />
    <child
      link="downIMU_link" />
    <axis
      xyz="0 0 0" />
  </joint>
  <link
    name="down_cmd_yaw">
    <inertial>
      <origin
        xyz="0.00176932022118864 0.00318242369356199 0.0165777735974686"
        rpy="0 0 0" />
      <mass
        value="0.270321194423816" />
      <inertia
        ixx="9.30502191917516E-05"
        ixy="5.09228965635076E-07"
        ixz="-2.53194388076669E-07"
        iyy="9.36474121125396E-05"
        iyz="-4.13967758871522E-07"
        izz="0.000150964050879269" />
    </inertial>
    <visual>
      <origin
        xyz="0 0 0"
        rpy="0 0 0" />
      <geometry>
        <mesh
          filename="package://sentry/meshes/down_cmd_yaw.STL" />
      </geometry>
      <material
        name="">
        <color
          rgba="0.196078431372549 0.196078431372549 0.196078431372549 1" />
      </material>
    </visual>
    <collision>
      <origin
        xyz="0 0 0"
        rpy="0 0 0" />
      <geometry>
        <mesh
          filename="package://sentry/meshes/down_cmd_yaw.STL" />
      </geometry>
    </collision>
  </link>
  <joint
    name="down_cmd_yaw_joint"
    type="continuous">
    <origin
      xyz="0.0536977787423807 0.016602230748367 -0.221717561495653"
      rpy="0.0898032331201576 -0.298684450448947 0" />
    <parent
      link="downIMU_link" />
    <child
      link="down_cmd_yaw" />
    <axis
      xyz="0 0 1" />
  </joint>
  <link
    name="down_cmd_pitch">
    <inertial>
      <origin
        xyz="-9.40778241089457E-05 -0.00128392205900212 -8.58231020903211E-05"
        rpy="0 0 0" />
      <mass
        value="0.270321194880469" />
      <inertia
        ixx="9.33657510789278E-05"
        ixy="-3.38171197506199E-07"
        ixz="5.90073832358512E-07"
        iyy="0.000150964051025031"
        iyz="-3.48018652682225E-07"
        izz="9.33318803148193E-05" />
    </inertial>
    <visual>
      <origin
        xyz="0 0 0"
        rpy="0 0 0" />
      <geometry>
        <mesh
          filename="package://sentry/meshes/down_cmd_pitch.STL" />
      </geometry>
      <material
        name="">
        <color
          rgba="0.196078431372549 0.196078431372549 0.196078431372549 1" />
      </material>
    </visual>
    <collision>
      <origin
        xyz="0 0 0"
        rpy="0 0 0" />
      <geometry>
        <mesh
          filename="package://sentry/meshes/down_cmd_pitch.STL" />
      </geometry>
    </collision>
  </link>
  <joint
    name="down_cmd_pitch__joint"
    type="continuous">
    <origin
      xyz="-0.118526757550704 0.0659675113061449 -0.0399884594735937"
      rpy="0.0939396250069834 0 0" />
    <parent
      link="downIMU_link" />
    <child
      link="down_cmd_pitch" />
    <axis
      xyz="0.026390278382864 -0.999618983043742 0.00808961961225604" />
  </joint>
</robot>